<?xml version='1.0' encoding='UTF-8'?>
<robot xmlns:sensor="http://playerstage.sourceforge.net/gazebo/xmlschema/#sensor" xmlns:controller="http://playerstage.sourceforge.net/gazebo/xmlschema/#controller" xmlns:interface="http://playerstage.sourceforge.net/gazebo/xmlschema/#interface" xmlns:xacro="http://ros.org/wiki/xacro" name="pioneer3dx">

  <xacro:include filename="$(find rocs_simulation)/urdf_model/defs/pioneer3dx_wheel.xacro"/>

<!-- Chassis -->
	<link name="base_link">
		<inertial>
			<mass value="3.5"/>
			<!--<origin xyz="-0.025 0 -0.223"/>-->
			<origin xyz="-0.05 0 0"/>
			<inertia ixx="1" ixy="0" ixz="0" iyy="1" iyz="0" izz="1"/>
		</inertial>
		<visual name="base_visual">
			<origin xyz="-0.045 0 0.148" rpy="0 0 0"/>
			<geometry name="pioneer_geom">
				<mesh filename="package://rocs_simulation/urdf_model/meshes/p3dx_meshes/chassis.stl"/>
			</geometry>
			<material name="ChassisRed">
				<color rgba="0.851 0.0 0.0 1.0"/>
			</material>
		</visual>
		<collision>
			<origin xyz="-0.045 0 0.145" rpy="0 0 0"/>
				<geometry>
					<box size="0.35 0.25 0.14"/>
				</geometry>
		</collision>
	</link>

	<gazebo reference="base_link">
		<material value="Gazebo/Red"/>
	</gazebo>

<!-- Top -->
	<link name="top_plate">
		<inertial>
			<mass value="0.01"/>	
			<origin xyz="0 0 0"/>
			<inertia ixx="1" ixy="0" ixz="0" iyy="1" iyz="0" izz="1"/>
		</inertial>
		<visual name="base_visual">
			<origin xyz="0 0 0" rpy="0 0 0"/>
			<geometry name="top_geom">
				<mesh filename="package://rocs_simulation/urdf_model/meshes/p3dx_meshes/top.stl"/>
			</geometry>

			<material name="TopBlack">
					<color rgba="0.038 0.038 0.038 1.0"/>
			</material>
		</visual>
		<collision>
			<origin xyz="0.0 0 0" rpy="0 0 0"/>
			<geometry name="pioneer_geom">
				<box size="0.45 0.38 0.01"/>
			</geometry>
		</collision>
	</link>
	<gazebo reference="top_plate">
		<material value="Gazebo/Black"/>
	</gazebo>


	<joint name="base_top_joint" type="fixed">
		<origin xyz="-0.045 0 0.234" rpy="0 0 0"/>
		<parent link="base_link"/>
		<child link="top_plate"/>
	</joint>



<!-- Swivel -->
	<link name="swivel">
		<inertial>
			<mass value="0.1"/>	
			<origin xyz="0 0 0"/>
			<inertia ixx="0.01" ixy="0" ixz="0" iyy="0.01" iyz="0" izz="0.01"/>
  	 	</inertial>
	<visual name="base_visual">
		<origin xyz="0 0 0" rpy="0 0 0"/>
		<geometry name="pioneer_geom">
			<mesh filename="package://rocs_simulation/urdf_model/meshes/p3dx_meshes/swivel.stl"/>
		</geometry>
		<material name="swivel">
			<color rgba="0.5 0.5 0.5 1"/>
		</material>
	</visual>
	<collision>
		<origin xyz="0 0 0" rpy="0 0 0"/>
		<geometry>
			<box size="0 0 0"/>
		</geometry>
	</collision>
	</link>
	<gazebo reference="swivel">
		<material value="Gazebo/Grey"/>
	</gazebo>


 	<joint name="base_swivel_joint" type="continuous">
		<origin xyz="-0.185 0 0.055" rpy="0 0 0"/>
		<axis xyz="0 0 1"/>
		<anchor xyz="0 0 0"/>
    <limit effort="100" velocity="100" k_velocity="0"/>
    <joint_properties damping="0.0" friction="0.0"/>
		<parent link="base_link"/>
		<child link="swivel"/>
	</joint>

<!-- Center Wheel + Hubcap -->
	<link name="center_hubcap">
		<inertial>
			<mass value="0.01"/>	
			<origin xyz="0 0 0"/>
			<inertia ixx="0.012411765597" ixy="-0.000711733678" ixz="0.00050272983" iyy="0.015218160428" iyz="-0.000004273467" izz="0.011763977943"/>
  	 	</inertial>
	<visual name="base_visual">
		<origin xyz="0 0 0" rpy="0 0 0"/>
		<geometry name="pioneer_geom">
			<mesh filename="package://rocs_simulation/urdf_model/meshes/p3dx_meshes/center_hubcap.stl"/>
		</geometry>
		<material name="swivel">
			<color rgba="0.5 0.5 0.5 1"/>
		</material>
	</visual>
	<collision>
		<origin xyz="0 0 0" rpy="0 0 0"/>
		<geometry>
			<box size="0 0 0"/>
		</geometry>
	</collision>
	</link>
	<gazebo reference="center_hubcap">
		<material value="Gazebo/Grey"/>
	</gazebo>

	<joint name="swivel_hubcap_joint" type="continuous">
		<origin xyz="-0.026 0 -0.016" rpy="0 0 0"/>
		<axis xyz="0 1 0"/>
		<anchor xyz="0 0 0"/>
    <limit effort="100" velocity="100" k_velocity="0"/>
    <joint_properties damping="0.0" friction="0.0"/>
	  <parent link="swivel"/>
		<child link="center_wheel"/>
	</joint>

	<link name="center_wheel">
		<inertial>
			<mass value="0.1"/>	
			<origin xyz="0 0 0"/>
			<inertia ixx="0.012411765597" ixy="-0.000711733678" ixz="0.00050272983" iyy="0.015218160428" iyz="-0.000004273467" izz="0.011763977943"/>
  	 	</inertial>
	<visual name="base_visual">
		<origin xyz="0 0 0" rpy="0 0 0"/>
		<geometry name="pioneer_geom">
			<mesh filename="package://rocs_simulation/urdf_model/meshes/p3dx_meshes/center_wheel.stl"/>
		</geometry>
		<material name="WheelBlack">
			<color rgba="0.117 0.117 0.117 1"/>
		</material>
	</visual>
	<collision>
		<origin xyz="0 0 0" rpy="${-3.1415927/2.0} 0 0"/>
		<geometry>
			<!--<mesh filename="package://rocs_simulation/urdf_model/meshes/p3dx_meshes/center_wheel.stl"/>-->
			<cylinder radius="0.0375" length="0.01"/>
		</geometry>
	</collision>
	</link>

	<joint name="center_wheel_joint" type="fixed">
		<origin xyz="-0.0035 0 -0.001" rpy="0 0 0"/>
		<parent link="center_wheel"/>
		<child link="center_hubcap"/>
	</joint>

	<gazebo reference="center_wheel">
		<material value="Gazebo/Black"/>
    <elem key="mu1" value="10.0"/>
    <elem key="mu2" value="10.0"/>
    <elem key="kp" value="1000000.0"/>
    <elem key="kd" value="1.0"/>
	</gazebo>


<xacro:p3dx_wheel suffix="left" parent="base_link" reflect="1"/>
<xacro:p3dx_wheel suffix="right" parent="base_link" reflect="-1"/>

<!-- Front + Back Sonar -->
	<link name="front_sonar">
		<inertial>
			<mass value="0.0001"/>	
			<origin xyz="0 0 0"/>
			<inertia ixx="1" ixy="0" ixz="0" iyy="1" iyz="0" izz="1"/>
		</inertial>
		<visual name="base_visual">
			<origin xyz="0 0 0" rpy="0 0 0"/>
			<geometry name="pioneer_geom">
				<mesh filename="package://rocs_simulation/urdf_model/meshes/p3dx_meshes/front_sonar.stl"/>
			</geometry>
			<material name="SonarYellow">
				<color rgba="0.715 0.583 0.210 1.0"/>
			</material>
		</visual>
		<collision>
			<origin xyz="0 0 0" rpy="0 0 0"/>
			<geometry>
				<box size="0 0 0"/>
			</geometry>
		</collision>
	</link>

	<gazebo reference="front_sonar">
		<material value="Gazebo/Yellow"/>
	</gazebo>

	<joint name="base_front_joint" type="fixed">
		<origin xyz="-0.198 0 0.208" rpy="0 0 0"/>
		<parent link="base_link"/>
		<child link="front_sonar"/>
	</joint>

	<link name="back_sonar">
		<inertial>
			<mass value="0.0001"/>	
			<origin xyz="0 0 0"/>
			<inertia ixx="1" ixy="0" ixz="0" iyy="1" iyz="0" izz="1"/>
		</inertial>
		<visual name="back_sonar_vis">
			<origin xyz="0 0 0" rpy="0 0 0"/>
			<geometry name="pioneer_geom">
				<mesh filename="package://rocs_simulation/urdf_model/meshes/p3dx_meshes/back_sonar.stl"/>
			</geometry>
			<material name="SonarYellow">
				<color rgba="0.715 0.583 0.210 1.0"/>
			</material>
		</visual>
		<collision>
			<origin xyz="0 0 0" rpy="0 0 0"/>
			<geometry>
				<box size="0 0 0"/>
			</geometry>
		</collision>
	</link>

	<gazebo reference="back_sonar">
		<material value="Gazebo/Yellow"/>
	</gazebo>

	<joint name="base_back_joint" type="fixed">
		<origin xyz="0.109 0 0.209" rpy="0 0 0"/>
		<parent link="base_link"/>
		<child link="back_sonar"/>
	</joint>
	
<!-- MY EDIT -->
<xacro:macro name="easy_cylinder" params="name radius length *vorigin *corigin *material">
	<link name="${name}">
	<visual>
		<xacro:insert_block name="vorigin"/>
		<geometry>
			<cylinder radius="${radius}" length="${length}"/>
		</geometry>
		<xacro:insert_block name="material"/>
	</visual>
	<collision>
		<xacro:insert_block name="corigin"/>
		<geometry>
			<cylinder radius="${radius}" length="${length}"/>
		</geometry>
	</collision>
	</link>
</xacro:macro>
<xacro:macro name="easy_box" params="name size *vorigin *corigin *material">
	<link name="${name}">
		<visual>
			<xacro:insert_block name="vorigin"/>
			<geometry>
				<box size="${size}"/>
			</geometry>
			<xacro:insert_block name="material"/>
		</visual>
		<collision>
			<xacro:insert_block name="corigin"/>
			<geometry>
				<box size="${size}"/>
			</geometry>
		</collision>
	</link>
</xacro:macro>
<xacro:macro name="fixedjoint" params="name parent child *origin">
	<joint name="${name}" type="fixed">
		<xacro:insert_block name="origin"/>
		<parent link="${parent}"/>
		<child link="${child}"/>
	</joint>
</xacro:macro>
<xacro:macro name="fixedlink" params="name parent child *origin">
	<link name="${name}">
		<xacro:insert_block name="origin"/>
		<parent link="${parent}"/>
		<child link="${child}"/>
	</link>
</xacro:macro>
<xacro:easy_box name="ptu_base" size="0.04 .07 .05">
	<origin xyz="0 0.015 0"/>
	<origin xyz="0 0.015 0"/>
	<material name="black"/>
</xacro:easy_box>
<xacro:fixedjoint name="toptubase" parent="base_link" child="ptu_base">
	<origin xyz="0.12 0 1.3" rpy="0 0.18 0"/><!--0.04  0.18-->
</xacro:fixedjoint>
<xacro:easy_box name="ptu_piece" size="0.04 .04 .06">
	<origin/><origin/>
	<material name="black"/>
</xacro:easy_box>

<joint name="pan" type="continuous">
	<origin xyz="0 0 .055"/>
	<axis xyz="0 0 1"/>
	<parent link="ptu_base"/>
	<child link="ptu_piece"/>
</joint>
<xacro:easy_box name="ptu_mount" size="0.04 .27 .03">
	<origin/><origin/>
	<material name="gray"/>
</xacro:easy_box>

<joint name="tilt" type="continuous">
	<origin xyz="0 0 .035"/>
	<axis xyz="0 -1 0"/>
	<parent link="ptu_piece"/>
	<child link="ptu_mount"/>
</joint>
<xacro:property name="pi" value="3.1415926535897931" />
<xacro:easy_box name="base_laser" size="0.04 .04 .05">
	<origin xyz="0 0.0 0"/>
<origin xyz="0 0.0 0"/>
	<material name="black"/>
</xacro:easy_box>
<xacro:easy_box name="hokuyo_laser" size="0.04 .04 .05">
	<origin xyz="0 0.0 0"/>
<origin xyz="0 0.0 0"/>
	<material name="black"/>
</xacro:easy_box>
<xacro:easy_box name="camera_link" size="0.04 .1 .04">
	<origin xyz="0 0.0 0"/>
<origin xyz="0 0.0 0"/>
	<material name="black"/>
</xacro:easy_box>
<xacro:easy_box name="marker_link" size="0.04 .1 .04">
	<origin xyz="0 0.0 0"/>
<origin xyz="0 0.0 0"/>
	<material name="black"/>
</xacro:easy_box>
<xacro:fixedjoint name="base_link_to_laser" parent="base_link" child="base_laser">
	<origin xyz="0.15 0 0.27" rpy="0 0 0"/>
</xacro:fixedjoint>
<xacro:fixedjoint name="sick_to_hokoyu" parent="base_laser" child="hokuyo_laser">
	<origin xyz="0 0 -0.225" rpy="${pi} 0 0"/>
</xacro:fixedjoint>
<xacro:fixedjoint name="ptu-to-kinect" parent="ptu_mount" child="camera_link">
	<origin xyz="0 0 0" rpy="0 0 0"/>
</xacro:fixedjoint>
<xacro:fixedjoint name="base-to-marker" parent="base_link" child="marker_link">
	<origin xyz="-0.03396034613251686 0.021506832912564278 1.5665124654769897" quaternion="-0.010930481087287964 0.023745126415032226 -0.0036445054224936743  0.9996516448918393"/>
</xacro:fixedjoint>

			

  <gazebo>
    <controller:differential_position2d name="controller1">
      <update>100</update>
      <leftJoint>base_right_wheel_joint</leftJoint>
      <rightJoint>base_left_wheel_joint</rightJoint>
      <wheelSeparation>0.39</wheelSeparation>
      <wheelDiameter>0.15</wheelDiameter>
      <torque>5</torque>


      <interface:position name="position_iface_0"/>
    </controller:differential_position2d>

    <controller:gazebo_ros_p3d name="p3d_base_controller" plugin="libgazebo_ros_p3d.so">
      <alwaysOn>true</alwaysOn>
      <updateRate>100.0</updateRate>
      <bodyName>base_link</bodyName>
      <topicName>base_pose_ground_truth</topicName>
      <gaussianNoise>0.01</gaussianNoise>
      <frameName>map</frameName>
      <xyzOffsets>0 0 0</xyzOffsets> <!-- initialize odometry for fake localization-->
      <rpyOffsets>0 0 0</rpyOffsets>
      <interface:position name="p3d_base_position"/>
    </controller:gazebo_ros_p3d>

    <!-- this publishes empty joint_states due to no transmission, but
         triggering robot_state_puublisher to publish tf between fixed joints in erratic,
         (e.g. base_laser_link for the base_scan frame) -->
    <controller:gazebo_ros_controller_manager name="gazebo_ros_controller_manager" plugin="libgazebo_ros_controller_manager.so">
      <alwaysOn>true</alwaysOn>
      <updateRate>1000.0</updateRate>
      <interface:audio name="gazebo_ros_controller_manager_dummy_iface"/>
    </controller:gazebo_ros_controller_manager>
  </gazebo>

</robot>


